<?xml version="1.0"?>
<robot name="roscontrol" xmlns:xacro="http://www.ros.org/wiki/xacro">
  <xacro:property name="width" value="0.2"/>
  <xacro:property name="length" value="0.4"/>
  <xacro:property name="height" value="0.1"/>
  <xacro:property name="wheeldia" value="0.15"/>
  <xacro:property name="spheredia" value="0.15"/>
  <xacro:property name="pi" value="3.1415"/>

  <material name="blue">
    <color rgba="0 0 0.8 1"/>
  </material>

  <material name="red">
    <color rgba="1 0 0 1"/>
  </material>

  <xacro:macro name="robot_inertia" params="mass">
    <inertial>
      <mass value="${mass}"/>
      <inertia ixx="1.0" ixy="0.0" ixz="0.0" iyy="1.0" iyz="0.0" izz="1.0"/>
    </inertial>
  </xacro:macro>

  <link name="chasis">
    <visual>
      <geometry>
        <box size="${width} ${length} ${height}"/>
      </geometry>
    </visual>
    <xacro:robot_inertia mass="2"/>
    <collision name='caster_collision'>
      <origin xyz="0 0.15 -0.03" rpy=" 0 0 0"/>
      <geometry>
        <sphere radius="0.05"/>
      </geometry>
      <surface>
        <friction>
          <ode>
            <mu>0</mu>
            <mu2>0</mu2>
            <slip1>1.0</slip1>
            <slip2>1.0</slip2>
          </ode>
        </friction>
      </surface>
    </collision>

    <visual name='caster_visual'>
      <origin xyz="0 0.15 -0.03" rpy=" 0 0 0"/>
      <geometry>
        <sphere radius="0.05"/>
      </geometry>
    </visual>

    <collision name='caster_front_collision'>
      <origin xyz="0 0.15 -0.03" rpy=" 0 0 0"/>
      <geometry>
        <sphere radius="0.05"/>
      </geometry>
      <surface>
        <friction>
          <ode>
            <mu>0</mu>
            <mu2>0</mu2>
            <slip1>1.0</slip1>
            <slip2>1.0</slip2>
          </ode>
        </friction>
      </surface>
    </collision>

    <visual name='caster_front_visual'>
      <origin xyz="0 0.15 -0.03" rpy=" 0 0 0"/>
      <geometry>
        <sphere radius="0.05"/>
      </geometry>
    </visual>
  </link>
<!-- code for right wheel -->
  <link name="right_wheel">
    <visual>
      <geometry>
        <cylinder length="${length/8}" radius="${wheeldia/2}"/>
      </geometry>
      <origin rpy="0 ${pi/2} 0" xyz="+0.15 0 0 "/>
      <material name="blue"/>
    </visual> 
    <collision>
      <geometry>
        <cylinder length="${length/8}" radius="${wheeldia/2}"/>
      </geometry>
      <origin rpy="0 ${pi/2} 0" xyz="+0.15 0 0 "/>
    </collision>
    <xacro:robot_inertia mass="0.2"/>   
  </link>

  <joint name="chasis_right_wheel" type="continuous">
    <parent link="chasis"/>
    <child link="right_wheel"/>
    <origin xyz="0 -0.15 0"/>
  </joint> 
<!-- code for left wheel --> 
  <link name="left_wheel">
    <visual>
      <geometry>
        <cylinder length="${length/8}" radius="${wheeldia/2}"/>
      </geometry>
      <origin rpy="0 ${pi/2} 0" xyz="-0.15 0 0 "/>
      <material name="blue"/>
    </visual>  
    <collision>
      <geometry>
        <cylinder length="${length/8}" radius="${wheeldia/2}"/>
      </geometry>
      <origin rpy="0 ${pi/2} 0" xyz="-0.15 0 0 "/>
    </collision>
    <xacro:robot_inertia mass="0.2"/>   
  </link>
  <joint name="chasis_left_wheel" type="continuous">
    <parent link="chasis"/>
    <child link="left_wheel"/>
    <origin xyz="0 -0.15 0"/>
  </joint>
 
  <gazebo>
    <plugin name="gazebo_ros_control" filename="libgazebo_ros_control.so">
      <robotNamespace>/</robotNamespace>
    </plugin>
  </gazebo>

</robot>








					

    
	
